Traceback (most recent call last):
  File "/home/va/Documents/remote/google-maps-scraper/venv/lib/python3.11/site-packages/urllib3/connection.py", line 200, in _new_conn
    sock = connection.create_connection(
           ^^^^^^^^^^^^^^^^^^^^^^^^^^^^^
  File "/home/va/Documents/remote/google-maps-scraper/venv/lib/python3.11/site-packages/urllib3/util/connection.py", line 85, in create_connection
    raise err
  File "/home/va/Documents/remote/google-maps-scraper/venv/lib/python3.11/site-packages/urllib3/util/connection.py", line 73, in create_connection
    sock.connect(sa)
ConnectionRefusedError: [Errno 111] Connection refused

The above exception was the direct cause of the following exception:

Traceback (most recent call last):
  File "/home/va/Documents/remote/google-maps-scraper/venv/lib/python3.11/site-packages/urllib3/connectionpool.py", line 790, in urlopen
    response = self._make_request(
               ^^^^^^^^^^^^^^^^^^^
  File "/home/va/Documents/remote/google-maps-scraper/venv/lib/python3.11/site-packages/urllib3/connectionpool.py", line 496, in _make_request
    conn.request(
  File "/home/va/Documents/remote/google-maps-scraper/venv/lib/python3.11/site-packages/urllib3/connection.py", line 388, in request
    self.endheaders()
  File "/usr/lib/python3.11/http/client.py", line 1277, in endheaders
    self._send_output(message_body, encode_chunked=encode_chunked)
  File "/usr/lib/python3.11/http/client.py", line 1037, in _send_output
    self.send(msg)
  File "/usr/lib/python3.11/http/client.py", line 975, in send
    self.connect()
  File "/home/va/Documents/remote/google-maps-scraper/venv/lib/python3.11/site-packages/urllib3/connection.py", line 236, in connect
    self.sock = self._new_conn()
                ^^^^^^^^^^^^^^^^
  File "/home/va/Documents/remote/google-maps-scraper/venv/lib/python3.11/site-packages/urllib3/connection.py", line 215, in _new_conn
    raise NewConnectionError(
urllib3.exceptions.NewConnectionError: <urllib3.connection.HTTPConnection object at 0x7f34b381c190>: Failed to establish a new connection: [Errno 111] Connection refused

The above exception was the direct cause of the following exception:

Traceback (most recent call last):
  File "/home/va/Documents/remote/google-maps-scraper/venv/lib/python3.11/site-packages/bose/base_task.py", line 117, in run_task
    self.run(driver)
  File "/home/va/Documents/remote/google-maps-scraper/src/scraper.py", line 232, in run
    result = get_data()
             ^^^^^^^^^^
  File "/home/va/Documents/remote/google-maps-scraper/src/scraper.py", line 220, in get_data
    a = get_maps_data(links)
        ^^^^^^^^^^^^^^^^^^^^
  File "/home/va/Documents/remote/google-maps-scraper/src/scraper.py", line 199, in get_maps_data
    ls = list(map(get_data, links))
         ^^^^^^^^^^^^^^^^^^^^^^^^^^
  File "/home/va/Documents/remote/google-maps-scraper/src/scraper.py", line 140, in get_data
    driver.get_by_current_page_referrer(link)
  File "/home/va/Documents/remote/google-maps-scraper/venv/lib/python3.11/site-packages/bose/boss_driver.py", line 22, in get_by_current_page_referrer
    self.execute_script(f"""
  File "/home/va/Documents/remote/google-maps-scraper/venv/lib/python3.11/site-packages/selenium/webdriver/remote/webdriver.py", line 500, in execute_script
    return self.execute(command, {"script": script, "args": converted_args})["value"]
           ^^^^^^^^^^^^^^^^^^^^^^^^^^^^^^^^^^^^^^^^^^^^^^^^^^^^^^^^^^^^^^^^^
  File "/home/va/Documents/remote/google-maps-scraper/venv/lib/python3.11/site-packages/selenium/webdriver/remote/webdriver.py", line 438, in execute
    response = self.command_executor.execute(driver_command, params)
               ^^^^^^^^^^^^^^^^^^^^^^^^^^^^^^^^^^^^^^^^^^^^^^^^^^^^^
  File "/home/va/Documents/remote/google-maps-scraper/venv/lib/python3.11/site-packages/selenium/webdriver/remote/remote_connection.py", line 290, in execute
    return self._request(command_info[0], url, body=data)
           ^^^^^^^^^^^^^^^^^^^^^^^^^^^^^^^^^^^^^^^^^^^^^^
  File "/home/va/Documents/remote/google-maps-scraper/venv/lib/python3.11/site-packages/selenium/webdriver/remote/remote_connection.py", line 311, in _request
    response = self._conn.request(method, url, body=body, headers=headers)
               ^^^^^^^^^^^^^^^^^^^^^^^^^^^^^^^^^^^^^^^^^^^^^^^^^^^^^^^^^^^
  File "/home/va/Documents/remote/google-maps-scraper/venv/lib/python3.11/site-packages/urllib3/_request_methods.py", line 118, in request
    return self.request_encode_body(
           ^^^^^^^^^^^^^^^^^^^^^^^^^
  File "/home/va/Documents/remote/google-maps-scraper/venv/lib/python3.11/site-packages/urllib3/_request_methods.py", line 217, in request_encode_body
    return self.urlopen(method, url, **extra_kw)
           ^^^^^^^^^^^^^^^^^^^^^^^^^^^^^^^^^^^^^
  File "/home/va/Documents/remote/google-maps-scraper/venv/lib/python3.11/site-packages/urllib3/poolmanager.py", line 433, in urlopen
    response = conn.urlopen(method, u.request_uri, **kw)
               ^^^^^^^^^^^^^^^^^^^^^^^^^^^^^^^^^^^^^^^^^
  File "/home/va/Documents/remote/google-maps-scraper/venv/lib/python3.11/site-packages/urllib3/connectionpool.py", line 874, in urlopen
    return self.urlopen(
           ^^^^^^^^^^^^^
  File "/home/va/Documents/remote/google-maps-scraper/venv/lib/python3.11/site-packages/urllib3/connectionpool.py", line 874, in urlopen
    return self.urlopen(
           ^^^^^^^^^^^^^
  File "/home/va/Documents/remote/google-maps-scraper/venv/lib/python3.11/site-packages/urllib3/connectionpool.py", line 874, in urlopen
    return self.urlopen(
           ^^^^^^^^^^^^^
  File "/home/va/Documents/remote/google-maps-scraper/venv/lib/python3.11/site-packages/urllib3/connectionpool.py", line 844, in urlopen
    retries = retries.increment(
              ^^^^^^^^^^^^^^^^^^
  File "/home/va/Documents/remote/google-maps-scraper/venv/lib/python3.11/site-packages/urllib3/util/retry.py", line 515, in increment
    raise MaxRetryError(_pool, url, reason) from reason  # type: ignore[arg-type]
    ^^^^^^^^^^^^^^^^^^^^^^^^^^^^^^^^^^^^^^^^^^^^^^^^^^^
urllib3.exceptions.MaxRetryError: HTTPConnectionPool(host='localhost', port=36997): Max retries exceeded with url: /session/ed03a14bb4e097e87af84b62ce37302f/execute/sync (Caused by NewConnectionError('<urllib3.connection.HTTPConnection object at 0x7f34b381c190>: Failed to establish a new connection: [Errno 111] Connection refused'))
