Traceback (most recent call last):
  File "/home/vagif/Documents/remote/bionluk/googleMapScraper/.venv/lib/python3.10/site-packages/urllib3/connection.py", line 174, in _new_conn
    conn = connection.create_connection(
  File "/home/vagif/Documents/remote/bionluk/googleMapScraper/.venv/lib/python3.10/site-packages/urllib3/util/connection.py", line 95, in create_connection
    raise err
  File "/home/vagif/Documents/remote/bionluk/googleMapScraper/.venv/lib/python3.10/site-packages/urllib3/util/connection.py", line 85, in create_connection
    sock.connect(sa)
ConnectionRefusedError: [Errno 111] Connection refused

During handling of the above exception, another exception occurred:

Traceback (most recent call last):
  File "/home/vagif/Documents/remote/bionluk/googleMapScraper/.venv/lib/python3.10/site-packages/urllib3/connectionpool.py", line 714, in urlopen
    httplib_response = self._make_request(
  File "/home/vagif/Documents/remote/bionluk/googleMapScraper/.venv/lib/python3.10/site-packages/urllib3/connectionpool.py", line 415, in _make_request
    conn.request(method, url, **httplib_request_kw)
  File "/home/vagif/Documents/remote/bionluk/googleMapScraper/.venv/lib/python3.10/site-packages/urllib3/connection.py", line 244, in request
    super(HTTPConnection, self).request(method, url, body=body, headers=headers)
  File "/usr/lib/python3.10/http/client.py", line 1282, in request
    self._send_request(method, url, body, headers, encode_chunked)
  File "/usr/lib/python3.10/http/client.py", line 1328, in _send_request
    self.endheaders(body, encode_chunked=encode_chunked)
  File "/usr/lib/python3.10/http/client.py", line 1277, in endheaders
    self._send_output(message_body, encode_chunked=encode_chunked)
  File "/usr/lib/python3.10/http/client.py", line 1037, in _send_output
    self.send(msg)
  File "/usr/lib/python3.10/http/client.py", line 975, in send
    self.connect()
  File "/home/vagif/Documents/remote/bionluk/googleMapScraper/.venv/lib/python3.10/site-packages/urllib3/connection.py", line 205, in connect
    conn = self._new_conn()
  File "/home/vagif/Documents/remote/bionluk/googleMapScraper/.venv/lib/python3.10/site-packages/urllib3/connection.py", line 186, in _new_conn
    raise NewConnectionError(
urllib3.exceptions.NewConnectionError: <urllib3.connection.HTTPConnection object at 0x7fb3eba26770>: Failed to establish a new connection: [Errno 111] Connection refused

During handling of the above exception, another exception occurred:

Traceback (most recent call last):
  File "/home/vagif/Documents/remote/bionluk/googleMapScraper/.venv/lib/python3.10/site-packages/bose/base_task.py", line 117, in run_task
    self.run(driver)
  File "/home/vagif/Documents/remote/bionluk/googleMapScraper/src/scraper.py", line 291, in run
    result = get_data(self.scroll_times)
  File "/home/vagif/Documents/remote/bionluk/googleMapScraper/src/scraper.py", line 279, in get_data
    a = get_maps_data(links)
  File "/home/vagif/Documents/remote/bionluk/googleMapScraper/src/scraper.py", line 258, in get_maps_data
    ls = list(map(get_data, links))
  File "/home/vagif/Documents/remote/bionluk/googleMapScraper/src/scraper.py", line 202, in get_data
    image_gall = driver.find_elements(By.CLASS_NAME, "DaSXdd")
  File "/home/vagif/Documents/remote/bionluk/googleMapScraper/.venv/lib/python3.10/site-packages/selenium/webdriver/remote/webdriver.py", line 889, in find_elements
    return self.execute(Command.FIND_ELEMENTS, {
  File "/home/vagif/Documents/remote/bionluk/googleMapScraper/.venv/lib/python3.10/site-packages/selenium/webdriver/remote/webdriver.py", line 427, in execute
    response = self.command_executor.execute(driver_command, params)
  File "/home/vagif/Documents/remote/bionluk/googleMapScraper/.venv/lib/python3.10/site-packages/selenium/webdriver/remote/remote_connection.py", line 344, in execute
    return self._request(command_info[0], url, body=data)
  File "/home/vagif/Documents/remote/bionluk/googleMapScraper/.venv/lib/python3.10/site-packages/selenium/webdriver/remote/remote_connection.py", line 366, in _request
    response = self._conn.request(method, url, body=body, headers=headers)
  File "/home/vagif/Documents/remote/bionluk/googleMapScraper/.venv/lib/python3.10/site-packages/urllib3/request.py", line 78, in request
    return self.request_encode_body(
  File "/home/vagif/Documents/remote/bionluk/googleMapScraper/.venv/lib/python3.10/site-packages/urllib3/request.py", line 170, in request_encode_body
    return self.urlopen(method, url, **extra_kw)
  File "/home/vagif/Documents/remote/bionluk/googleMapScraper/.venv/lib/python3.10/site-packages/urllib3/poolmanager.py", line 376, in urlopen
    response = conn.urlopen(method, u.request_uri, **kw)
  File "/home/vagif/Documents/remote/bionluk/googleMapScraper/.venv/lib/python3.10/site-packages/urllib3/connectionpool.py", line 826, in urlopen
    return self.urlopen(
  File "/home/vagif/Documents/remote/bionluk/googleMapScraper/.venv/lib/python3.10/site-packages/urllib3/connectionpool.py", line 826, in urlopen
    return self.urlopen(
  File "/home/vagif/Documents/remote/bionluk/googleMapScraper/.venv/lib/python3.10/site-packages/urllib3/connectionpool.py", line 826, in urlopen
    return self.urlopen(
  File "/home/vagif/Documents/remote/bionluk/googleMapScraper/.venv/lib/python3.10/site-packages/urllib3/connectionpool.py", line 798, in urlopen
    retries = retries.increment(
  File "/home/vagif/Documents/remote/bionluk/googleMapScraper/.venv/lib/python3.10/site-packages/urllib3/util/retry.py", line 592, in increment
    raise MaxRetryError(_pool, url, error or ResponseError(cause))
urllib3.exceptions.MaxRetryError: HTTPConnectionPool(host='localhost', port=58995): Max retries exceeded with url: /session/b34918e778695060b1afb04204a58899/elements (Caused by NewConnectionError('<urllib3.connection.HTTPConnection object at 0x7fb3eba26770>: Failed to establish a new connection: [Errno 111] Connection refused'))
