Traceback (most recent call last):
  File "/home/va/Documents/remote/google-maps-scraper/src/scraper.py", line 198, in get_data
    opened_days[1].click()
  File "/home/va/Documents/remote/google-maps-scraper/venv/lib/python3.11/site-packages/selenium/webdriver/remote/webelement.py", line 94, in click
    self._execute(Command.CLICK_ELEMENT)
  File "/home/va/Documents/remote/google-maps-scraper/venv/lib/python3.11/site-packages/selenium/webdriver/remote/webelement.py", line 403, in _execute
    return self._parent.execute(command, params)
           ^^^^^^^^^^^^^^^^^^^^^^^^^^^^^^^^^^^^^
  File "/home/va/Documents/remote/google-maps-scraper/venv/lib/python3.11/site-packages/selenium/webdriver/remote/webdriver.py", line 440, in execute
    self.error_handler.check_response(response)
  File "/home/va/Documents/remote/google-maps-scraper/venv/lib/python3.11/site-packages/selenium/webdriver/remote/errorhandler.py", line 245, in check_response
    raise exception_class(message, screen, stacktrace)
selenium.common.exceptions.ElementNotInteractableException: Message: element not interactable
  (Session info: chrome=113.0.5672.126)
Stacktrace:
#0 0x55edd9580b73 <unknown>
#1 0x55edd92c92a0 <unknown>
#2 0x55edd9306f94 <unknown>
#3 0x55edd92fbe8a <unknown>
#4 0x55edd9325632 <unknown>
#5 0x55edd92fb7b3 <unknown>
#6 0x55edd93257fe <unknown>
#7 0x55edd933db3e <unknown>
#8 0x55edd9325403 <unknown>
#9 0x55edd92f9f0a <unknown>
#10 0x55edd92faffe <unknown>
#11 0x55edd9541c4e <unknown>
#12 0x55edd95458f2 <unknown>
#13 0x55edd954e870 <unknown>
#14 0x55edd9546933 <unknown>
#15 0x55edd951a75e <unknown>
#16 0x55edd9568e48 <unknown>
#17 0x55edd9568fd7 <unknown>
#18 0x55edd9578e39 <unknown>
#19 0x7f2585c94b43 <unknown>


During handling of the above exception, another exception occurred:

Traceback (most recent call last):
  File "/home/va/Documents/remote/google-maps-scraper/venv/lib/python3.11/site-packages/bose/base_task.py", line 117, in run_task
    self.run(driver)
  File "/home/va/Documents/remote/google-maps-scraper/src/scraper.py", line 262, in run
    result = get_data()
             ^^^^^^^^^^
  File "/home/va/Documents/remote/google-maps-scraper/src/scraper.py", line 250, in get_data
    a = get_maps_data(links)
        ^^^^^^^^^^^^^^^^^^^^
  File "/home/va/Documents/remote/google-maps-scraper/src/scraper.py", line 229, in get_maps_data
    ls = list(map(get_data, links))
         ^^^^^^^^^^^^^^^^^^^^^^^^^^
  File "/home/va/Documents/remote/google-maps-scraper/src/scraper.py", line 201, in get_data
    opened_days[0].click()
    ~~~~~~~~~~~^^^
IndexError: list index out of range
